2023-08-18 16:10:12,330 - ERROR - TCP connection to device failed.

Common causes of this problem are:
1. Incorrect hostname or IP address.
2. Wrong TCP port.
3. Intermediate firewall blocking access.

Device settings: fortinet 10.224.28.1:2221


2023-08-18 16:10:12,330 - ERROR - Error en el FW 10.224.28.1
2023-08-18 16:10:22,362 - ERROR - TCP connection to device failed.

Common causes of this problem are:
1. Incorrect hostname or IP address.
2. Wrong TCP port.
3. Intermediate firewall blocking access.

Device settings: fortinet 10.224.113.97:2221


2023-08-18 16:10:22,362 - ERROR - Error en el FW 10.224.113.97
2023-08-18 16:10:32,393 - ERROR - TCP connection to device failed.

Common causes of this problem are:
1. Incorrect hostname or IP address.
2. Wrong TCP port.
3. Intermediate firewall blocking access.

Device settings: fortinet 10.224.113.129:2221


2023-08-18 16:10:32,393 - ERROR - Error en el FW 10.224.113.129
2023-08-18 16:10:42,435 - ERROR - TCP connection to device failed.

Common causes of this problem are:
1. Incorrect hostname or IP address.
2. Wrong TCP port.
3. Intermediate firewall blocking access.

Device settings: fortinet 10.224.113.161:2221


2023-08-18 16:10:42,436 - ERROR - Error en el FW 10.224.113.161
2023-08-18 16:10:52,467 - ERROR - TCP connection to device failed.

Common causes of this problem are:
1. Incorrect hostname or IP address.
2. Wrong TCP port.
3. Intermediate firewall blocking access.

Device settings: fortinet 10.224.21.1:2221


2023-08-18 16:10:52,467 - ERROR - Error en el FW 10.224.21.1
2023-08-22 11:22:48,737 - ERROR - local variable 'e' referenced before assignment
2023-08-22 11:22:48,746 - ERROR - Error en el FW 10.224.126.89
2023-08-22 11:22:48,746 - ERROR - local variable 'fecha_y_hora' referenced before assignment
2023-08-22 11:22:48,747 - ERROR - Error en el FW 10.224.126.89
2023-08-22 11:25:18,107 - ERROR - TCP connection to device failed.

Common causes of this problem are:
1. Incorrect hostname or IP address.
2. Wrong TCP port.
3. Intermediate firewall blocking access.

Device settings: fortinet 10.224.28.1:2221


2023-08-22 11:25:18,107 - ERROR - Error en el FW 10.224.28.1
2023-08-22 11:25:28,136 - ERROR - TCP connection to device failed.

Common causes of this problem are:
1. Incorrect hostname or IP address.
2. Wrong TCP port.
3. Intermediate firewall blocking access.

Device settings: fortinet 10.224.113.97:2221


2023-08-22 11:25:28,137 - ERROR - Error en el FW 10.224.113.97
2023-08-22 11:25:38,177 - ERROR - TCP connection to device failed.

Common causes of this problem are:
1. Incorrect hostname or IP address.
2. Wrong TCP port.
3. Intermediate firewall blocking access.

Device settings: fortinet 10.224.113.129:2221


2023-08-22 11:25:38,177 - ERROR - Error en el FW 10.224.113.129
2023-08-22 11:25:48,214 - ERROR - TCP connection to device failed.

Common causes of this problem are:
1. Incorrect hostname or IP address.
2. Wrong TCP port.
3. Intermediate firewall blocking access.

Device settings: fortinet 10.224.113.161:2221


2023-08-22 11:25:48,214 - ERROR - Error en el FW 10.224.113.161
2023-08-22 11:25:58,254 - ERROR - TCP connection to device failed.

Common causes of this problem are:
1. Incorrect hostname or IP address.
2. Wrong TCP port.
3. Intermediate firewall blocking access.

Device settings: fortinet 10.224.21.1:2221


2023-08-22 11:25:58,254 - ERROR - Error en el FW 10.224.21.1
2023-08-22 11:25:58,288 - ERROR - 1146 (42S02): Table 'dcs.fechas_consultas_firewalls' doesn't exist
2023-08-22 11:25:58,288 - ERROR - Error en el FW 10.224.21.1
2023-08-22 11:28:09,936 - ERROR - TCP connection to device failed.

Common causes of this problem are:
1. Incorrect hostname or IP address.
2. Wrong TCP port.
3. Intermediate firewall blocking access.

Device settings: fortinet 10.224.28.1:2221


2023-08-22 11:28:09,936 - ERROR - Error en el FW 10.224.28.1
2023-08-22 11:28:19,978 - ERROR - TCP connection to device failed.

Common causes of this problem are:
1. Incorrect hostname or IP address.
2. Wrong TCP port.
3. Intermediate firewall blocking access.

Device settings: fortinet 10.224.113.97:2221


2023-08-22 11:28:19,978 - ERROR - Error en el FW 10.224.113.97
2023-08-22 11:28:30,016 - ERROR - TCP connection to device failed.

Common causes of this problem are:
1. Incorrect hostname or IP address.
2. Wrong TCP port.
3. Intermediate firewall blocking access.

Device settings: fortinet 10.224.113.129:2221


2023-08-22 11:28:30,016 - ERROR - Error en el FW 10.224.113.129
2023-08-22 11:28:40,043 - ERROR - TCP connection to device failed.

Common causes of this problem are:
1. Incorrect hostname or IP address.
2. Wrong TCP port.
3. Intermediate firewall blocking access.

Device settings: fortinet 10.224.113.161:2221


2023-08-22 11:28:40,043 - ERROR - Error en el FW 10.224.113.161
2023-08-22 11:28:50,064 - ERROR - TCP connection to device failed.

Common causes of this problem are:
1. Incorrect hostname or IP address.
2. Wrong TCP port.
3. Intermediate firewall blocking access.

Device settings: fortinet 10.224.21.1:2221


2023-08-22 11:28:50,064 - ERROR - Error en el FW 10.224.21.1
2023-08-22 11:28:50,091 - ERROR - 1146 (42S02): Table 'dcs.fechas_consultas_fw' doesn't exist
2023-08-22 11:28:50,091 - ERROR - Error en el FW 10.224.21.1
2023-08-22 11:32:26,260 - ERROR - TCP connection to device failed.

Common causes of this problem are:
1. Incorrect hostname or IP address.
2. Wrong TCP port.
3. Intermediate firewall blocking access.

Device settings: fortinet 10.224.28.1:2221


2023-08-22 11:32:26,260 - ERROR - Error en el FW 10.224.28.1
2023-08-22 11:32:36,289 - ERROR - TCP connection to device failed.

Common causes of this problem are:
1. Incorrect hostname or IP address.
2. Wrong TCP port.
3. Intermediate firewall blocking access.

Device settings: fortinet 10.224.113.97:2221


2023-08-22 11:32:36,289 - ERROR - Error en el FW 10.224.113.97
2023-08-22 11:32:46,322 - ERROR - TCP connection to device failed.

Common causes of this problem are:
1. Incorrect hostname or IP address.
2. Wrong TCP port.
3. Intermediate firewall blocking access.

Device settings: fortinet 10.224.113.129:2221


2023-08-22 11:32:46,323 - ERROR - Error en el FW 10.224.113.129
2023-08-22 11:32:56,358 - ERROR - TCP connection to device failed.

Common causes of this problem are:
1. Incorrect hostname or IP address.
2. Wrong TCP port.
3. Intermediate firewall blocking access.

Device settings: fortinet 10.224.113.161:2221


2023-08-22 11:32:56,358 - ERROR - Error en el FW 10.224.113.161
2023-08-22 11:33:06,395 - ERROR - TCP connection to device failed.

Common causes of this problem are:
1. Incorrect hostname or IP address.
2. Wrong TCP port.
3. Intermediate firewall blocking access.

Device settings: fortinet 10.224.21.1:2221


2023-08-22 11:33:06,395 - ERROR - Error en el FW 10.224.21.1
2023-08-24 08:31:57,391 - ERROR - TCP connection to device failed.

Common causes of this problem are:
1. Incorrect hostname or IP address.
2. Wrong TCP port.
3. Intermediate firewall blocking access.

Device settings: fortinet 10.224.28.1:2221


2023-08-24 08:31:57,393 - ERROR - Error en el FW 10.224.28.1
2023-08-24 08:32:07,413 - ERROR - TCP connection to device failed.

Common causes of this problem are:
1. Incorrect hostname or IP address.
2. Wrong TCP port.
3. Intermediate firewall blocking access.

Device settings: fortinet 10.224.113.97:2221


2023-08-24 08:32:07,413 - ERROR - Error en el FW 10.224.113.97
2023-08-24 08:32:17,454 - ERROR - TCP connection to device failed.

Common causes of this problem are:
1. Incorrect hostname or IP address.
2. Wrong TCP port.
3. Intermediate firewall blocking access.

Device settings: fortinet 10.224.113.129:2221


2023-08-24 08:32:17,454 - ERROR - Error en el FW 10.224.113.129
2023-08-24 08:32:27,483 - ERROR - TCP connection to device failed.

Common causes of this problem are:
1. Incorrect hostname or IP address.
2. Wrong TCP port.
3. Intermediate firewall blocking access.

Device settings: fortinet 10.224.113.161:2221


2023-08-24 08:32:27,483 - ERROR - Error en el FW 10.224.113.161
2023-08-24 08:32:37,511 - ERROR - TCP connection to device failed.

Common causes of this problem are:
1. Incorrect hostname or IP address.
2. Wrong TCP port.
3. Intermediate firewall blocking access.

Device settings: fortinet 10.224.21.1:2221


2023-08-24 08:32:37,511 - ERROR - Error en el FW 10.224.21.1
2023-08-24 09:01:20,571 - ERROR - TCP connection to device failed.

Common causes of this problem are:
1. Incorrect hostname or IP address.
2. Wrong TCP port.
3. Intermediate firewall blocking access.

Device settings: fortinet 10.224.28.1:2221


2023-08-24 09:01:20,571 - ERROR - Error en el FW 10.224.28.1
2023-08-24 09:01:30,612 - ERROR - TCP connection to device failed.

Common causes of this problem are:
1. Incorrect hostname or IP address.
2. Wrong TCP port.
3. Intermediate firewall blocking access.

Device settings: fortinet 10.224.113.97:2221


2023-08-24 09:01:30,612 - ERROR - Error en el FW 10.224.113.97
2023-08-24 09:01:40,637 - ERROR - TCP connection to device failed.

Common causes of this problem are:
1. Incorrect hostname or IP address.
2. Wrong TCP port.
3. Intermediate firewall blocking access.

Device settings: fortinet 10.224.113.129:2221


2023-08-24 09:01:40,637 - ERROR - Error en el FW 10.224.113.129
2023-08-24 09:01:50,672 - ERROR - TCP connection to device failed.

Common causes of this problem are:
1. Incorrect hostname or IP address.
2. Wrong TCP port.
3. Intermediate firewall blocking access.

Device settings: fortinet 10.224.113.161:2221


2023-08-24 09:01:50,672 - ERROR - Error en el FW 10.224.113.161
2023-08-24 09:02:00,708 - ERROR - TCP connection to device failed.

Common causes of this problem are:
1. Incorrect hostname or IP address.
2. Wrong TCP port.
3. Intermediate firewall blocking access.

Device settings: fortinet 10.224.21.1:2221


2023-08-24 09:02:00,708 - ERROR - Error en el FW 10.224.21.1
2023-08-24 09:05:27,708 - ERROR - TCP connection to device failed.

Common causes of this problem are:
1. Incorrect hostname or IP address.
2. Wrong TCP port.
3. Intermediate firewall blocking access.

Device settings: fortinet 10.224.28.1:2221


2023-08-24 09:05:27,708 - ERROR - Error en el FW 10.224.28.1
2023-08-24 09:05:37,745 - ERROR - TCP connection to device failed.

Common causes of this problem are:
1. Incorrect hostname or IP address.
2. Wrong TCP port.
3. Intermediate firewall blocking access.

Device settings: fortinet 10.224.113.97:2221


2023-08-24 09:05:37,745 - ERROR - Error en el FW 10.224.113.97
2023-08-24 09:05:47,778 - ERROR - TCP connection to device failed.

Common causes of this problem are:
1. Incorrect hostname or IP address.
2. Wrong TCP port.
3. Intermediate firewall blocking access.

Device settings: fortinet 10.224.113.129:2221


2023-08-24 09:05:47,778 - ERROR - Error en el FW 10.224.113.129
2023-08-24 09:05:57,808 - ERROR - TCP connection to device failed.

Common causes of this problem are:
1. Incorrect hostname or IP address.
2. Wrong TCP port.
3. Intermediate firewall blocking access.

Device settings: fortinet 10.224.113.161:2221


2023-08-24 09:05:57,808 - ERROR - Error en el FW 10.224.113.161
2023-08-24 09:06:07,848 - ERROR - TCP connection to device failed.

Common causes of this problem are:
1. Incorrect hostname or IP address.
2. Wrong TCP port.
3. Intermediate firewall blocking access.

Device settings: fortinet 10.224.21.1:2221


2023-08-24 09:06:07,848 - ERROR - Error en el FW 10.224.21.1
2023-08-24 09:08:21,622 - ERROR - TCP connection to device failed.

Common causes of this problem are:
1. Incorrect hostname or IP address.
2. Wrong TCP port.
3. Intermediate firewall blocking access.

Device settings: fortinet 10.224.28.1:2221


2023-08-24 09:08:21,622 - ERROR - Error en el FW 10.224.28.1
2023-08-24 09:08:31,660 - ERROR - TCP connection to device failed.

Common causes of this problem are:
1. Incorrect hostname or IP address.
2. Wrong TCP port.
3. Intermediate firewall blocking access.

Device settings: fortinet 10.224.113.97:2221


2023-08-24 09:08:31,660 - ERROR - Error en el FW 10.224.113.97
2023-08-24 09:08:41,698 - ERROR - TCP connection to device failed.

Common causes of this problem are:
1. Incorrect hostname or IP address.
2. Wrong TCP port.
3. Intermediate firewall blocking access.

Device settings: fortinet 10.224.113.129:2221


2023-08-24 09:08:41,698 - ERROR - Error en el FW 10.224.113.129
2023-08-24 09:08:51,725 - ERROR - TCP connection to device failed.

Common causes of this problem are:
1. Incorrect hostname or IP address.
2. Wrong TCP port.
3. Intermediate firewall blocking access.

Device settings: fortinet 10.224.113.161:2221


2023-08-24 09:08:51,725 - ERROR - Error en el FW 10.224.113.161
2023-08-24 09:09:01,765 - ERROR - TCP connection to device failed.

Common causes of this problem are:
1. Incorrect hostname or IP address.
2. Wrong TCP port.
3. Intermediate firewall blocking access.

Device settings: fortinet 10.224.21.1:2221


2023-08-24 09:09:01,765 - ERROR - Error en el FW 10.224.21.1
2023-08-24 09:38:48,422 - ERROR - TCP connection to device failed.

Common causes of this problem are:
1. Incorrect hostname or IP address.
2. Wrong TCP port.
3. Intermediate firewall blocking access.

Device settings: fortinet 10.224.28.1:2221


2023-08-24 09:38:48,422 - ERROR - Error en el FW 10.224.28.1
2023-08-24 09:38:58,465 - ERROR - TCP connection to device failed.

Common causes of this problem are:
1. Incorrect hostname or IP address.
2. Wrong TCP port.
3. Intermediate firewall blocking access.

Device settings: fortinet 10.224.113.97:2221


2023-08-24 09:38:58,465 - ERROR - Error en el FW 10.224.113.97
2023-08-24 09:39:08,502 - ERROR - TCP connection to device failed.

Common causes of this problem are:
1. Incorrect hostname or IP address.
2. Wrong TCP port.
3. Intermediate firewall blocking access.

Device settings: fortinet 10.224.113.129:2221


2023-08-24 09:39:08,503 - ERROR - Error en el FW 10.224.113.129
2023-08-24 09:39:18,539 - ERROR - TCP connection to device failed.

Common causes of this problem are:
1. Incorrect hostname or IP address.
2. Wrong TCP port.
3. Intermediate firewall blocking access.

Device settings: fortinet 10.224.113.161:2221


2023-08-24 09:39:18,539 - ERROR - Error en el FW 10.224.113.161
2023-08-24 09:39:28,569 - ERROR - TCP connection to device failed.

Common causes of this problem are:
1. Incorrect hostname or IP address.
2. Wrong TCP port.
3. Intermediate firewall blocking access.

Device settings: fortinet 10.224.21.1:2221


2023-08-24 09:39:28,569 - ERROR - Error en el FW 10.224.21.1
2023-08-24 10:18:32,898 - ERROR - TCP connection to device failed.

Common causes of this problem are:
1. Incorrect hostname or IP address.
2. Wrong TCP port.
3. Intermediate firewall blocking access.

Device settings: fortinet 10.224.113.129:2221


2023-08-24 10:18:32,898 - ERROR - Error en el FW 10.224.113.129
2023-08-24 10:19:18,376 - ERROR - local variable 'e' referenced before assignment
2023-08-24 10:19:18,376 - ERROR - Error en el FW 10.224.113.161
2023-08-24 10:20:05,045 - ERROR - local variable 'e' referenced before assignment
2023-08-24 10:20:05,045 - ERROR - Error en el FW 10.224.21.1
2023-08-24 10:25:48,407 - ERROR - Error en el FW 10.224.113.129
2023-08-24 10:25:48,407 - ERROR - TCP connection to device failed.

Common causes of this problem are:
1. Incorrect hostname or IP address.
2. Wrong TCP port.
3. Intermediate firewall blocking access.

Device settings: fortinet 10.224.113.129:2221


2023-08-24 10:26:25,411 - ERROR - No se encontro las palabras 'Health Check - FW 10.224.113.161
2023-08-24 10:27:14,235 - ERROR - No se encontro las palabras 'Health Check - FW 10.224.21.1
2023-08-24 10:57:49,104 - ERROR - No se encontro las palabras 'Health Check - FW 10.224.113.129
2023-08-24 10:58:23,009 - ERROR - No se encontro las palabras 'Health Check - FW 10.224.113.161
2023-08-24 10:59:12,882 - ERROR - No se encontro las palabras 'Health Check - FW 10.224.21.1
2023-08-25 14:32:39,031 - ERROR: Error Controladora Device 10.117.115.110
2023-08-25 14:32:39,031 - ERROR: Error Controladora Device 10.117.115.110
2023-08-25 14:32:39,032 - ERROR: Traceback (most recent call last):
  File "/home/donkami/Sona/SistemaDCS/DCS-Candelaria/Services/Mesh/controladora.py", line 38, in get_data_controladora
    output = net_connect.send_command("sh wireless client mac-address " + data_pala.split()[0] + " detail")
IndexError: list index out of range

2023-08-25 14:32:39,032 - ERROR: Traceback (most recent call last):
  File "/home/donkami/Sona/SistemaDCS/DCS-Candelaria/Services/Mesh/controladora.py", line 38, in get_data_controladora
    output = net_connect.send_command("sh wireless client mac-address " + data_pala.split()[0] + " detail")
IndexError: list index out of range

2023-08-25 14:33:41,589 - ERROR: Error Controladora Device 10.117.115.181
2023-08-25 14:33:41,589 - ERROR: Error Controladora Device 10.117.115.181
2023-08-25 14:33:41,589 - ERROR: Traceback (most recent call last):
  File "/home/donkami/Sona/SistemaDCS/DCS-Candelaria/Services/Mesh/controladora.py", line 38, in get_data_controladora
    output = net_connect.send_command("sh wireless client mac-address " + data_pala.split()[0] + " detail")
IndexError: list index out of range

2023-08-25 14:33:41,589 - ERROR: Traceback (most recent call last):
  File "/home/donkami/Sona/SistemaDCS/DCS-Candelaria/Services/Mesh/controladora.py", line 38, in get_data_controladora
    output = net_connect.send_command("sh wireless client mac-address " + data_pala.split()[0] + " detail")
IndexError: list index out of range

2023-08-25 14:35:26,107 - ERROR: Error Controladora Device 10.117.115.184
2023-08-25 14:35:26,107 - ERROR: Error Controladora Device 10.117.115.184
2023-08-25 14:35:26,108 - ERROR: Traceback (most recent call last):
  File "/home/donkami/Sona/SistemaDCS/DCS-Candelaria/Services/Mesh/controladora.py", line 38, in get_data_controladora
    output = net_connect.send_command("sh wireless client mac-address " + data_pala.split()[0] + " detail")
IndexError: list index out of range

2023-08-25 14:35:26,108 - ERROR: Traceback (most recent call last):
  File "/home/donkami/Sona/SistemaDCS/DCS-Candelaria/Services/Mesh/controladora.py", line 38, in get_data_controladora
    output = net_connect.send_command("sh wireless client mac-address " + data_pala.split()[0] + " detail")
IndexError: list index out of range

2023-08-25 14:35:50,403 - ERROR: Error Controladora Device 10.117.115.110
2023-08-25 14:35:50,403 - ERROR: Error Controladora Device 10.117.115.110
2023-08-25 14:35:50,404 - ERROR: Traceback (most recent call last):
  File "/home/donkami/Sona/SistemaDCS/DCS-Candelaria/Services/Mesh/controladora.py", line 38, in get_data_controladora
    output = net_connect.send_command("sh wireless client mac-address " + data_pala.split()[0] + " detail")
IndexError: list index out of range

2023-08-25 14:35:50,404 - ERROR: Traceback (most recent call last):
  File "/home/donkami/Sona/SistemaDCS/DCS-Candelaria/Services/Mesh/controladora.py", line 38, in get_data_controladora
    output = net_connect.send_command("sh wireless client mac-address " + data_pala.split()[0] + " detail")
IndexError: list index out of range

2023-08-25 14:42:10,554 - ERROR: Error Controladora Device 10.117.115.110
2023-08-25 14:42:10,554 - ERROR: Error Controladora Device 10.117.115.110
2023-08-25 14:42:10,555 - ERROR: Traceback (most recent call last):
  File "/home/donkami/Sona/SistemaDCS/DCS-Candelaria/Services/Mesh/controladora.py", line 38, in get_data_controladora
    output = net_connect.send_command("sh wireless client mac-address " + data_pala.split()[0] + " detail")
IndexError: list index out of range

2023-08-25 14:42:10,555 - ERROR: Traceback (most recent call last):
  File "/home/donkami/Sona/SistemaDCS/DCS-Candelaria/Services/Mesh/controladora.py", line 38, in get_data_controladora
    output = net_connect.send_command("sh wireless client mac-address " + data_pala.split()[0] + " detail")
IndexError: list index out of range

2023-08-25 14:43:15,929 - ERROR: Error Controladora Device 10.117.115.181
2023-08-25 14:43:15,929 - ERROR: Error Controladora Device 10.117.115.181
2023-08-25 14:43:15,930 - ERROR: Traceback (most recent call last):
  File "/home/donkami/Sona/SistemaDCS/DCS-Candelaria/Services/Mesh/controladora.py", line 35, in get_data_controladora
    data_pala = net_connect.send_command(f"sh wireless client summary detail ipv4 | inc {device_ip}") #! Ip Pala
  File "/home/donkami/Sona/SistemaDCS/DCS-Candelaria/Services/Mesh/venv/lib/python3.10/site-packages/netmiko/utilities.py", line 592, in wrapper_decorator
    return func(self, *args, **kwargs)
  File "/home/donkami/Sona/SistemaDCS/DCS-Candelaria/Services/Mesh/venv/lib/python3.10/site-packages/netmiko/base_connection.py", line 1721, in send_command
    raise ReadTimeout(msg)
netmiko.exceptions.ReadTimeout: 
Pattern not detected: 'WLC\\-9800\\-MESH\\-CD>' in output.

Things you might try to fix this:
1. Explicitly set your pattern using the expect_string argument.
2. Increase the read_timeout to a larger value.

You can also look at the Netmiko session_log or debug log for more information.



2023-08-25 14:43:15,930 - ERROR: Traceback (most recent call last):
  File "/home/donkami/Sona/SistemaDCS/DCS-Candelaria/Services/Mesh/controladora.py", line 35, in get_data_controladora
    data_pala = net_connect.send_command(f"sh wireless client summary detail ipv4 | inc {device_ip}") #! Ip Pala
  File "/home/donkami/Sona/SistemaDCS/DCS-Candelaria/Services/Mesh/venv/lib/python3.10/site-packages/netmiko/utilities.py", line 592, in wrapper_decorator
    return func(self, *args, **kwargs)
  File "/home/donkami/Sona/SistemaDCS/DCS-Candelaria/Services/Mesh/venv/lib/python3.10/site-packages/netmiko/base_connection.py", line 1721, in send_command
    raise ReadTimeout(msg)
netmiko.exceptions.ReadTimeout: 
Pattern not detected: 'WLC\\-9800\\-MESH\\-CD>' in output.

Things you might try to fix this:
1. Explicitly set your pattern using the expect_string argument.
2. Increase the read_timeout to a larger value.

You can also look at the Netmiko session_log or debug log for more information.



2023-08-25 14:44:29,226 - ERROR: Error Controladora Device 10.117.115.182
2023-08-25 14:44:29,226 - ERROR: Error Controladora Device 10.117.115.182
2023-08-25 14:44:29,226 - ERROR: Traceback (most recent call last):
  File "/home/donkami/Sona/SistemaDCS/DCS-Candelaria/Services/Mesh/controladora.py", line 35, in get_data_controladora
    data_pala = net_connect.send_command(f"sh wireless client summary detail ipv4 | inc {device_ip}") #! Ip Pala
  File "/home/donkami/Sona/SistemaDCS/DCS-Candelaria/Services/Mesh/venv/lib/python3.10/site-packages/netmiko/utilities.py", line 592, in wrapper_decorator
    return func(self, *args, **kwargs)
  File "/home/donkami/Sona/SistemaDCS/DCS-Candelaria/Services/Mesh/venv/lib/python3.10/site-packages/netmiko/base_connection.py", line 1721, in send_command
    raise ReadTimeout(msg)
netmiko.exceptions.ReadTimeout: 
Pattern not detected: 'WLC\\-9800\\-MESH\\-CD>' in output.

Things you might try to fix this:
1. Explicitly set your pattern using the expect_string argument.
2. Increase the read_timeout to a larger value.

You can also look at the Netmiko session_log or debug log for more information.



2023-08-25 14:44:29,226 - ERROR: Traceback (most recent call last):
  File "/home/donkami/Sona/SistemaDCS/DCS-Candelaria/Services/Mesh/controladora.py", line 35, in get_data_controladora
    data_pala = net_connect.send_command(f"sh wireless client summary detail ipv4 | inc {device_ip}") #! Ip Pala
  File "/home/donkami/Sona/SistemaDCS/DCS-Candelaria/Services/Mesh/venv/lib/python3.10/site-packages/netmiko/utilities.py", line 592, in wrapper_decorator
    return func(self, *args, **kwargs)
  File "/home/donkami/Sona/SistemaDCS/DCS-Candelaria/Services/Mesh/venv/lib/python3.10/site-packages/netmiko/base_connection.py", line 1721, in send_command
    raise ReadTimeout(msg)
netmiko.exceptions.ReadTimeout: 
Pattern not detected: 'WLC\\-9800\\-MESH\\-CD>' in output.

Things you might try to fix this:
1. Explicitly set your pattern using the expect_string argument.
2. Increase the read_timeout to a larger value.

You can also look at the Netmiko session_log or debug log for more information.



2023-08-25 14:44:50,416 - ERROR: Error Controladora Device 10.117.115.183
2023-08-25 14:44:50,416 - ERROR: Error Controladora Device 10.117.115.183
2023-08-25 14:44:50,417 - ERROR: Traceback (most recent call last):
  File "/home/donkami/Sona/SistemaDCS/DCS-Candelaria/Services/Mesh/controladora.py", line 35, in get_data_controladora
    data_pala = net_connect.send_command(f"sh wireless client summary detail ipv4 | inc {device_ip}") #! Ip Pala
  File "/home/donkami/Sona/SistemaDCS/DCS-Candelaria/Services/Mesh/venv/lib/python3.10/site-packages/netmiko/utilities.py", line 592, in wrapper_decorator
    return func(self, *args, **kwargs)
  File "/home/donkami/Sona/SistemaDCS/DCS-Candelaria/Services/Mesh/venv/lib/python3.10/site-packages/netmiko/base_connection.py", line 1721, in send_command
    raise ReadTimeout(msg)
netmiko.exceptions.ReadTimeout: 
Pattern not detected: 'WLC\\-9800\\-MESH\\-CD>' in output.

Things you might try to fix this:
1. Explicitly set your pattern using the expect_string argument.
2. Increase the read_timeout to a larger value.

You can also look at the Netmiko session_log or debug log for more information.



2023-08-25 14:44:50,417 - ERROR: Traceback (most recent call last):
  File "/home/donkami/Sona/SistemaDCS/DCS-Candelaria/Services/Mesh/controladora.py", line 35, in get_data_controladora
    data_pala = net_connect.send_command(f"sh wireless client summary detail ipv4 | inc {device_ip}") #! Ip Pala
  File "/home/donkami/Sona/SistemaDCS/DCS-Candelaria/Services/Mesh/venv/lib/python3.10/site-packages/netmiko/utilities.py", line 592, in wrapper_decorator
    return func(self, *args, **kwargs)
  File "/home/donkami/Sona/SistemaDCS/DCS-Candelaria/Services/Mesh/venv/lib/python3.10/site-packages/netmiko/base_connection.py", line 1721, in send_command
    raise ReadTimeout(msg)
netmiko.exceptions.ReadTimeout: 
Pattern not detected: 'WLC\\-9800\\-MESH\\-CD>' in output.

Things you might try to fix this:
1. Explicitly set your pattern using the expect_string argument.
2. Increase the read_timeout to a larger value.

You can also look at the Netmiko session_log or debug log for more information.



2023-08-25 14:45:13,384 - ERROR: Error Controladora Device 10.117.115.184
2023-08-25 14:45:13,384 - ERROR: Error Controladora Device 10.117.115.184
2023-08-25 14:45:13,385 - ERROR: Traceback (most recent call last):
  File "/home/donkami/Sona/SistemaDCS/DCS-Candelaria/Services/Mesh/controladora.py", line 38, in get_data_controladora
    output = net_connect.send_command("sh wireless client mac-address " + data_pala.split()[0] + " detail")
IndexError: list index out of range

2023-08-25 14:45:13,385 - ERROR: Traceback (most recent call last):
  File "/home/donkami/Sona/SistemaDCS/DCS-Candelaria/Services/Mesh/controladora.py", line 38, in get_data_controladora
    output = net_connect.send_command("sh wireless client mac-address " + data_pala.split()[0] + " detail")
IndexError: list index out of range

2023-08-31 09:57:31,600 - ERROR - No se encontro las palabras 'Health Check - FW 10.224.113.129
2023-08-31 09:58:05,487 - ERROR - No se encontro las palabras 'Health Check - FW 10.224.113.161
2023-08-31 09:58:43,761 - ERROR - No se encontro las palabras 'Health Check - FW 10.224.21.1
2023-09-01 15:18:41,723 - ERROR - Error desconocido con la ip 10.230.127.1
2023-09-01 15:19:16,531 - ERROR - Error desconocido con la ip 10.230.127.1
2023-09-01 15:19:43,988 - ERROR - Error desconocido con la ip 10.230.127.1
2023-09-01 15:20:24,397 - ERROR - Error desconocido con la ip 10.230.127.1
2023-09-01 15:20:56,888 - ERROR - Error desconocido con la ip 10.230.127.1
2023-09-01 15:20:56,888 - ERROR - Error: local variable 'sensor_name' referenced before assignment
2023-09-01 15:21:31,281 - ERROR - Error desconocido con la ip 10.230.127.1
2023-09-01 15:21:31,281 - ERROR - Error: 'last_uptime_days'
2023-09-01 15:22:32,087 - ERROR - Error desconocido con la ip 10.230.127.1
2023-09-01 15:22:32,087 - ERROR - Error: 'last_uptime_days'
2023-09-01 15:22:32,097 - ERROR - TRAZABILIDAD: Traceback (most recent call last):
  File "/home/donkami/Sona/SistemaDCS/DCS-Candelaria/Services/WAN/uptime.py", line 108, in get_uptime
    save_bd(data_wan)
  File "/home/donkami/Sona/SistemaDCS/DCS-Candelaria/Services/WAN/uptime.py", line 213, in save_bd
    last_uptimedays = data_wan['last_uptime_days']
KeyError: 'last_uptime_days'

2023-09-01 15:24:45,452 - ERROR - Error desconocido con la ip 10.230.127.1
2023-09-01 15:24:45,452 - ERROR - Error: 'last_downpercent'
2023-09-01 15:24:45,452 - ERROR - TRAZABILIDAD: Traceback (most recent call last):
  File "/home/donkami/Sona/SistemaDCS/DCS-Candelaria/Services/WAN/uptime.py", line 108, in get_uptime
    save_bd(data_wan)
  File "/home/donkami/Sona/SistemaDCS/DCS-Candelaria/Services/WAN/uptime.py", line 216, in save_bd
    last_downtimepercent = data_wan['last_downpercent']
KeyError: 'last_downpercent'

2023-09-01 15:27:54,855 - ERROR - Error desconocido con la ip 10.230.127.1
2023-09-01 15:27:54,855 - ERROR - Error: 1064 (42000): You have an error in your SQL syntax; check the manual that corresponds to your MySQL server version for the right syntax to use near '29d 19h 38m 19s', '100', '00s', '0.0', '100', '100')' at line 1
2023-09-01 15:27:54,865 - ERROR - TRAZABILIDAD: Traceback (most recent call last):
  File "/home/donkami/Sona/SistemaDCS/DCS-Candelaria/Services/Mesh/venv/lib/python3.10/site-packages/mysql/connector/connection_cext.py", line 611, in cmd_query
    self._cmysql.query(
_mysql_connector.MySQLInterfaceError: You have an error in your SQL syntax; check the manual that corresponds to your MySQL server version for the right syntax to use near '29d 19h 38m 19s', '100', '00s', '0.0', '100', '100')' at line 1

The above exception was the direct cause of the following exception:

Traceback (most recent call last):
  File "/home/donkami/Sona/SistemaDCS/DCS-Candelaria/Services/WAN/uptime.py", line 108, in get_uptime
    save_bd(data_wan)
  File "/home/donkami/Sona/SistemaDCS/DCS-Candelaria/Services/WAN/uptime.py", line 223, in save_bd
    cursor.execute(query + values)
  File "/home/donkami/Sona/SistemaDCS/DCS-Candelaria/Services/Mesh/venv/lib/python3.10/site-packages/mysql/connector/cursor_cext.py", line 330, in execute
    result = self._cnx.cmd_query(
  File "/home/donkami/Sona/SistemaDCS/DCS-Candelaria/Services/Mesh/venv/lib/python3.10/site-packages/mysql/connector/connection_cext.py", line 619, in cmd_query
    raise get_mysql_exception(
mysql.connector.errors.ProgrammingError: 1064 (42000): You have an error in your SQL syntax; check the manual that corresponds to your MySQL server version for the right syntax to use near '29d 19h 38m 19s', '100', '00s', '0.0', '100', '100')' at line 1

2023-09-01 15:30:25,305 - ERROR - Data WAN: {'sensor_name': 'Not Found', 'last_uptimedays': 'Not Found', 'last_downtimedays': 'Not Found', 'last_uptimepercent': 'Not Found', 'last_downtimepercent': 'Not Found', 'current_uptimepercent': 'Not Found', 'today_uptimepercent': 'Not Found'}
2023-09-01 15:30:25,306 - ERROR - Error desconocido con la ip 20.226.31.2
2023-09-01 15:30:25,307 - ERROR - Error: 1265 (01000): Data truncated for column 'last_uptime_percent' at row 1
2023-09-01 15:30:25,307 - ERROR - TRAZABILIDAD: Traceback (most recent call last):
  File "/home/donkami/Sona/SistemaDCS/DCS-Candelaria/Services/Mesh/venv/lib/python3.10/site-packages/mysql/connector/connection_cext.py", line 611, in cmd_query
    self._cmysql.query(
_mysql_connector.MySQLInterfaceError: Data truncated for column 'last_uptime_percent' at row 1

The above exception was the direct cause of the following exception:

Traceback (most recent call last):
  File "/home/donkami/Sona/SistemaDCS/DCS-Candelaria/Services/WAN/uptime.py", line 69, in get_uptime
    save_bd(data_wan)
  File "/home/donkami/Sona/SistemaDCS/DCS-Candelaria/Services/WAN/uptime.py", line 223, in save_bd
    cursor.execute(query + values)
  File "/home/donkami/Sona/SistemaDCS/DCS-Candelaria/Services/Mesh/venv/lib/python3.10/site-packages/mysql/connector/cursor_cext.py", line 330, in execute
    result = self._cnx.cmd_query(
  File "/home/donkami/Sona/SistemaDCS/DCS-Candelaria/Services/Mesh/venv/lib/python3.10/site-packages/mysql/connector/connection_cext.py", line 619, in cmd_query
    raise get_mysql_exception(
mysql.connector.errors.DatabaseError: 1265 (01000): Data truncated for column 'last_uptime_percent' at row 1

2023-09-01 15:35:21,938 - ERROR - Data WAN: {'sensor_name': 'Not Found', 'last_uptimedays': 'Not Found', 'last_downtimedays': 'Not Found', 'last_uptimepercent': 0.0, 'last_downtimepercent': 0.0, 'current_uptimepercent': 0.0, 'today_uptimepercent': 0.0}
2023-09-01 15:38:09,033 - ERROR - Error desconocido con la ip 10.230.127.1
2023-09-01 15:38:09,033 - ERROR - Error: 1364 (HY000): Field 'ip' doesn't have a default value
2023-09-01 15:38:09,033 - ERROR - TRAZABILIDAD: Traceback (most recent call last):
  File "/home/donkami/Sona/SistemaDCS/DCS-Candelaria/Services/Mesh/venv/lib/python3.10/site-packages/mysql/connector/connection_cext.py", line 611, in cmd_query
    self._cmysql.query(
_mysql_connector.MySQLInterfaceError: Field 'ip' doesn't have a default value

The above exception was the direct cause of the following exception:

Traceback (most recent call last):
  File "/home/donkami/Sona/SistemaDCS/DCS-Candelaria/Services/WAN/uptime.py", line 103, in get_uptime
    save_bd(data_wan)
  File "/home/donkami/Sona/SistemaDCS/DCS-Candelaria/Services/WAN/uptime.py", line 218, in save_bd
    cursor.execute(query + values)
  File "/home/donkami/Sona/SistemaDCS/DCS-Candelaria/Services/Mesh/venv/lib/python3.10/site-packages/mysql/connector/cursor_cext.py", line 330, in execute
    result = self._cnx.cmd_query(
  File "/home/donkami/Sona/SistemaDCS/DCS-Candelaria/Services/Mesh/venv/lib/python3.10/site-packages/mysql/connector/connection_cext.py", line 619, in cmd_query
    raise get_mysql_exception(
mysql.connector.errors.DatabaseError: 1364 (HY000): Field 'ip' doesn't have a default value

2023-09-01 15:39:02,665 - ERROR - Error desconocido con la ip 10.230.127.1
2023-09-01 15:39:02,665 - ERROR - Error: 1265 (01000): Data truncated for column 'id' at row 1
2023-09-01 15:39:02,666 - ERROR - TRAZABILIDAD: Traceback (most recent call last):
  File "/home/donkami/Sona/SistemaDCS/DCS-Candelaria/Services/Mesh/venv/lib/python3.10/site-packages/mysql/connector/connection_cext.py", line 611, in cmd_query
    self._cmysql.query(
_mysql_connector.MySQLInterfaceError: Data truncated for column 'id' at row 1

The above exception was the direct cause of the following exception:

Traceback (most recent call last):
  File "/home/donkami/Sona/SistemaDCS/DCS-Candelaria/Services/WAN/uptime.py", line 103, in get_uptime
    save_bd(data_wan)
  File "/home/donkami/Sona/SistemaDCS/DCS-Candelaria/Services/WAN/uptime.py", line 219, in save_bd
    cursor.execute(query + values)
  File "/home/donkami/Sona/SistemaDCS/DCS-Candelaria/Services/Mesh/venv/lib/python3.10/site-packages/mysql/connector/cursor_cext.py", line 330, in execute
    result = self._cnx.cmd_query(
  File "/home/donkami/Sona/SistemaDCS/DCS-Candelaria/Services/Mesh/venv/lib/python3.10/site-packages/mysql/connector/connection_cext.py", line 619, in cmd_query
    raise get_mysql_exception(
mysql.connector.errors.DatabaseError: 1265 (01000): Data truncated for column 'id' at row 1

2023-09-01 15:39:57,789 - ERROR - Data WAN: {'ip': '20.226.31.2', 'sensor_name': 'Not Found', 'last_uptimedays': 'Not Found', 'last_downtimedays': 'Not Found', 'last_uptimepercent': 0.0, 'last_downtimepercent': 0.0, 'current_uptimepercent': 0.0, 'today_uptimepercent': 0.0}
2023-09-01 15:40:41,293 - ERROR - Data WAN: {'ip': '10.230.127.11x', 'sensor_name': 'Not Found', 'last_uptimedays': 'Not Found', 'last_downtimedays': 'Not Found', 'last_uptimepercent': 0.0, 'last_downtimepercent': 0.0, 'current_uptimepercent': 0.0, 'today_uptimepercent': 0.0}
